<?xml version="1.0" encoding="utf-8"?>
<!-- This URDF was automatically created by SolidWorks to URDF Exporter! Originally created by Stephen Brawner (brawner@gmail.com) 
     Commit Version: 1.6.0-4-g7f85cfe  Build Version: 1.6.7995.38578
     For more information, please see http://wiki.ros.org/sw_urdf_exporter -->
<robot
  name="Plain_Box_URDF">
  <link
    name="base_link">
    <inertial>
      <origin
        xyz="0.0056233 -0.01191 0.076147"
        rpy="0 0 0" />
      <mass
        value="0.65846" />
      <inertia
        ixx="0.0016062"
        ixy="2.4498E-06"
        ixz="1.3433E-06"
        iyy="0.0015646"
        iyz="3.5399E-07"
        izz="0.0014585" />
    </inertial>
    <visual>
      <origin
        xyz="0 0 0"
        rpy="0 0 0" />
      <geometry>
        <mesh
          filename="package://Plain_Box_URDF/meshes/base_link.STL" />
      </geometry>
      <material
        name="">
        <color
          rgba="0.79608 0.82353 0.93725 1" />
      </material>
    </visual>
    <collision>
      <origin
        xyz="0 0 0"
        rpy="0 0 0" />
      <geometry>
        <mesh
          filename="package://Plain_Box_URDF/meshes/base_link.STL" />
      </geometry>
    </collision>
  </link>
  <link
    name="top_Link">
    <inertial>
      <origin
        xyz="0.0012643 0.097693 -0.041107"
        rpy="0 0 0" />
      <mass
        value="0.40215" />
      <inertia
        ixx="0.00028852"
        ixy="-1.0819E-06"
        ixz="-9.1772E-08"
        iyy="0.00057584"
        iyz="-1.1657E-05"
        izz="0.00071659" />
    </inertial>
    <visual>
      <origin
        xyz="0 0 0"
        rpy="0 0 0" />
      <geometry>
        <mesh
          filename="package://Plain_Box_URDF/meshes/top_Link.STL" />
      </geometry>
      <material
        name="">
        <color
          rgba="0.79608 0.82353 0.93725 1" />
      </material>
    </visual>
    <collision>
      <origin
        xyz="0 0 0"
        rpy="0 0 0" />
      <geometry>
        <mesh
          filename="package://Plain_Box_URDF/meshes/top_Link.STL" />
      </geometry>
    </collision>
  </link>
  <joint
    name="joint_1"
    type="revolute">
    <origin
      xyz="0 -0.0050165 0.071196"
      rpy="2.8878 0 0" />
    <parent
      link="base_link" />
    <child
      link="top_Link" />
    <axis
      xyz="0 0 1" />
    <limit
      lower="0"
      upper="2"
      effort="100"
      velocity="10" />
    <dynamics
      friction="0.5" />
  </joint>
</robot>