<mujoco model="Plain_Box_URDF">
    <compiler angle="radian" />
    <size njmax="500" nconmax="100" />
    <asset>
        <mesh name="base_link" file="base_link.STL" />
        <mesh name="top_Link" file="top_Link.STL" />
    </asset>
    <worldbody>
        <geom type="mesh" rgba="0.79608 0.82353 0.93725 1" mesh="base_link" />
        <body name="top_Link" pos="0 -0.0050165 0.071196" quat="0.126556 0.991959 0 0">
        <!-- <body name="top_Link" pos="0 -0.0050165 0.071196" quat="0 0.126556 0.991959 0"> -->
            <inertial pos="0.0012643 0.097693 -0.041107" quat="-0.0303491 0.706453 -0.0276705 0.706567" mass="0.40215" diaginertia="0.000717549 0.000574885 0.000288516" />
            <joint name="joint_1" pos="0 0 0" axis="0 0 1" limited="true" range="0 2" frictionloss="0.5" />
            <geom type="mesh" rgba="0.79608 0.82353 0.93725 1" mesh="top_Link" />
        </body>
    </worldbody>
</mujoco>
