<mujoco model="plain_sw">
    <compiler angle="radian" />
    <size njmax="500" nconmax="100" />
    <asset>
        <mesh name="base_link" file="base_link.STL" />
        <mesh name="top_Link" file="top_Link.STL" />
    </asset>
    <worldbody>
        <body name="base">
            <geom type="mesh" rgba="0.796078 0.823529 0.937255 1" mesh="base_link" />
            <body name="top_Link" pos="0 0.071183 0.14422" quat="0.499998 0.5 -0.500002 -0.5">
                <inertial pos="0.0938686 0.0492173 -0.00126429" quat="0.706204 -0.00134102 -0.00133987 0.708006" mass="0.402154" diaginertia="0.000717544 0.000574886 0.000288512" />
                <joint name="joint_1" pos="0 0 0" axis="0 0 -1" limited="true" range="-2 0" frictionloss="0.5" />
                <geom type="mesh" rgba="0.796078 0.823529 0.937255 1" mesh="top_Link" />
            </body>
        </body>
    </worldbody>
    <contact>
        <exclude name="exclude_2_body_0" body1="base" body2="top_Link"/>
    </contact>
</mujoco>
