<mujoco model="slider_sw">
    <compiler angle="radian" />
    <size njmax="500" nconmax="100" />
    <asset>
        <mesh name="base_link" file="base_link.STL" />
        <mesh name="top_link" file="top_link.STL" />
        <mesh name="slider_link" file="slider_link.STL" />
    </asset>
    <worldbody>
        <geom type="mesh" rgba="0.79216 0.81961 0.93333 1" mesh="base_link" />
        <body name="top_link" pos="0.019609 0.14738 0.1474" quat="0.499998 0.5 0.500002 0.5">
            <inertial pos="-0.093935 0.049344 0.058002" quat="0.708027 -0.00408805 -0.00409188 0.706162" mass="0.28443" diaginertia="0.000504461 0.000406727 0.000201172" />
            <joint name="top_joint" pos="0 0 0" axis="0 0 -1" limited="true" range="-1.57 1.57" />
            <geom type="mesh" rgba="0.79216 0.81961 0.93333 1" mesh="top_link" />
        </body>
        <body name="slider_link" pos="0.009525 0 0.0889" quat="0.499998 -0.5 0.500002 -0.5">
            <inertial pos="0.014979 -0.0077014 0.010112" quat="0.403054 0.580988 -0.580988 0.403054" mass="0.019201" diaginertia="6.84616e-06 6.3796e-06 4.91554e-06" />
            <joint name="slider_joint" pos="0 0 0" axis="0 0 1" type="slide" limited="true" range="0 0.06" />
            <geom type="mesh" rgba="0.79216 0.81961 0.93333 1" mesh="slider_link" />
        </body>
    </worldbody>
</mujoco>
